<?xml version="1.0" ?>
<!-- =================================================================================== -->
<!-- |    This document was autogenerated by xacro from /tmp/tmpyk8yxmz0/flexiv_description/urdf/rizon.urdf.xacro | -->
<!-- |    EDITING THIS FILE BY HAND IS NOT RECOMMENDED                                 | -->
<!-- =================================================================================== -->
<robot name="Rizon4">
  <joint name="base_joint" type="fixed">
    <parent link="world"/>
    <child link="base_link"/>
    <origin rpy="0.0 0.0 0.0" xyz="0.0 0.0 0.0"/>
  </joint>
  <joint name="joint1" type="revolute">
    <parent link="base_link"/>
    <child link="link1"/>
    <origin rpy="0 0 -3.141592654" xyz="0 0 0.155"/>
    <axis xyz="0 0 1"/>
    <limit effort="123" lower="-2.8798" upper="2.8798" velocity="2.0944"/>
    <safety_controller k_position="100.0" k_velocity="40.0" soft_lower_limit="-2.7925" soft_upper_limit="2.7925"/>
  </joint>
  <joint name="joint2" type="revolute">
    <parent link="link1"/>
    <child link="link2"/>
    <origin rpy="0 0 0" xyz="0 0.03 0.21"/>
    <axis xyz="0 1 0"/>
    <limit effort="123" lower="-2.3562" upper="2.3562" velocity="2.0944"/>
    <safety_controller k_position="100.0" k_velocity="40.0" soft_lower_limit="-2.2689" soft_upper_limit="2.2689"/>
  </joint>
  <joint name="joint3" type="revolute">
    <parent link="link2"/>
    <child link="link3"/>
    <origin rpy="0 0 0" xyz="0 0.035 0.205"/>
    <axis xyz="0 0 1"/>
    <limit effort="64" lower="-3.0543" upper="3.0543" velocity="2.4435"/>
    <safety_controller k_position="100.0" k_velocity="40.0" soft_lower_limit="-2.9671" soft_upper_limit="2.9671"/>
  </joint>
  <joint name="joint4" type="revolute">
    <parent link="link3"/>
    <child link="link4"/>
    <origin rpy="0 0 -3.141592654" xyz="-0.02 -0.03 0.19"/>
    <axis xyz="0 1 0"/>
    <limit effort="64" lower="-1.9548" upper="2.7751" velocity="2.4435"/>
    <safety_controller k_position="100.0" k_velocity="40.0" soft_lower_limit="-1.8675" soft_upper_limit="2.6878"/>
  </joint>
  <joint name="joint5" type="revolute">
    <parent link="link4"/>
    <child link="link5"/>
    <origin rpy="0 0 -3.141592654" xyz="-0.02 0.025 0.195"/>
    <axis xyz="0 0 1"/>
    <limit effort="39" lower="-3.0543" upper="3.0543" velocity="4.8869"/>
    <safety_controller k_position="100.0" k_velocity="40.0" soft_lower_limit="-2.9671" soft_upper_limit="2.9671"/>
  </joint>
  <joint name="joint6" type="revolute">
    <parent link="link5"/>
    <child link="link6"/>
    <origin rpy="0 0 0" xyz="0 0.03 0.19"/>
    <axis xyz="0 1 0"/>
    <limit effort="39" lower="-1.4835" upper="4.6251" velocity="4.8869"/>
    <safety_controller k_position="100.0" k_velocity="40.0" soft_lower_limit="-1.3963" soft_upper_limit="4.5379"/>
  </joint>
  <joint name="joint7" type="revolute">
    <parent link="link6"/>
    <child link="link7"/>
    <origin rpy="0 -1.570796327 0" xyz="-0.015 0.073 0.11"/>
    <axis xyz="0 0 1"/>
    <limit effort="39" lower="-3.0543" upper="3.0543" velocity="4.8869"/>
    <safety_controller k_position="100.0" k_velocity="40.0" soft_lower_limit="-2.9671" soft_upper_limit="2.9671"/>
  </joint>
  <joint name="link7_to_flange" type="fixed">
    <parent link="link7"/>
    <child link="flange"/>
    <origin rpy="0 0 -3.141592654" xyz="0 0 0.081"/>
  </joint>
  <link name="world">
      </link>
  <link name="base_link">
    <origin rpy="0.0 0.0 0.0" xyz="0.0 -0.0 0.09"/>
    <mass value="3.8"/>
    <inertia ixx="0.02" ixy="0.0" ixz="0.0" iyy="0.02" iyz="0.0" izz="0.01"/>
    <visual name="shell">
      <origin rpy="0 0 0" xyz="0 0 0"/>
      <geometry>
        <mesh filename="package://flexiv_description/meshes/Rizon4/visual/link0.obj"/>
      </geometry>
    </visual>
    <collision name="convex_mesh">
      <origin rpy="0 0 0" xyz="0 0 0"/>
      <geometry>
        <mesh filename="package://flexiv_description/meshes/Rizon4/collision/link0.stl"/>
      </geometry>
    </collision>
    <workspace>
      <origin rpy="0.0 0.0 0.0" xyz="0.0 0.0 0.365"/>
      <geometry>
        <sphere radius="0.89"/>
      </geometry>
    </workspace>
  </link>
  <link name="link1">
    <origin rpy="0.0 0.0 0.0" xyz="0.0 0.0 0.15"/>
    <mass value="3.6"/>
    <inertia ixx="0.03" ixy="0.0" ixz="0.0" iyy="0.03" iyz="0.0" izz="0.01"/>
    <visual name="shell">
      <origin rpy="0 0 0" xyz="0 0 0"/>
      <geometry>
        <mesh filename="package://flexiv_description/meshes/Rizon4/visual/link1.obj"/>
      </geometry>
    </visual>
    <visual name="ring">
      <origin rpy="0.0 0.0 0.0" xyz="0.0 0.0 -0.0025"/>
      <geometry>
        <mesh filename="package://flexiv_description/meshes/Rizon4/visual/ring.obj" scale="0.062 0.062 0.002"/>
      </geometry>
    </visual>
    <collision name="convex_mesh">
      <origin rpy="0 0 0" xyz="0 0 0"/>
      <geometry>
        <mesh filename="package://flexiv_description/meshes/Rizon4/collision/link1.stl"/>
      </geometry>
    </collision>
  </link>
  <link name="link2">
    <origin rpy="0.0 0.0 0.0" xyz="-0.0 0.04 0.1"/>
    <mass value="2.7"/>
    <inertia ixx="0.02" ixy="0.0" ixz="0.0" iyy="0.02" iyz="-0.0003" izz="0.004"/>
    <visual name="shell">
      <origin rpy="0 0 0" xyz="0 0 0"/>
      <geometry>
        <mesh filename="package://flexiv_description/meshes/Rizon4/visual/link2.obj"/>
      </geometry>
    </visual>
    <visual name="ring">
      <origin rpy="1.570796327 0.0 0.0" xyz="0.0 -0.0025 0.0"/>
      <geometry>
        <mesh filename="package://flexiv_description/meshes/Rizon4/visual/ring.obj" scale="0.062 0.062 0.002"/>
      </geometry>
    </visual>
    <collision name="convex_mesh">
      <origin rpy="0 0 0" xyz="0 0 0"/>
      <geometry>
        <mesh filename="package://flexiv_description/meshes/Rizon4/collision/link2.stl"/>
      </geometry>
    </collision>
  </link>
  <link name="link3">
    <origin rpy="0.0 0.0 0.0" xyz="-0.01 -0.0 0.14"/>
    <mass value="2.4"/>
    <inertia ixx="0.01" ixy="0.0" ixz="-0.001" iyy="0.01" iyz="-0.0007" izz="0.004"/>
    <visual name="shell">
      <origin rpy="0 0 0" xyz="0 0 0"/>
      <geometry>
        <mesh filename="package://flexiv_description/meshes/Rizon4/visual/link3.obj"/>
      </geometry>
    </visual>
    <visual name="ring">
      <origin rpy="0.0 0.0 0.0" xyz="0.0 0.0 -0.0025"/>
      <geometry>
        <mesh filename="package://flexiv_description/meshes/Rizon4/visual/ring.obj" scale="0.051 0.051 0.002"/>
      </geometry>
    </visual>
    <collision name="convex_mesh">
      <origin rpy="0 0 0" xyz="0 0 0"/>
      <geometry>
        <mesh filename="package://flexiv_description/meshes/Rizon4/collision/link3.stl"/>
      </geometry>
    </collision>
  </link>
  <link name="link4">
    <origin rpy="0.0 0.0 0.0" xyz="-0.01 0.03 0.1"/>
    <mass value="2.4"/>
    <inertia ixx="0.02" ixy="0.0" ixz="-0.002" iyy="0.02" iyz="-0.001" izz="0.003"/>
    <visual name="shell">
      <origin rpy="0 0 0" xyz="0 0 0"/>
      <geometry>
        <mesh filename="package://flexiv_description/meshes/Rizon4/visual/link4.obj"/>
      </geometry>
    </visual>
    <visual name="ring">
      <origin rpy="1.570796327 0.0 0.0" xyz="0.0 -0.0025 0.0"/>
      <geometry>
        <mesh filename="package://flexiv_description/meshes/Rizon4/visual/ring.obj" scale="0.051 0.051 0.002"/>
      </geometry>
    </visual>
    <collision name="convex_mesh">
      <origin rpy="0 0 0" xyz="0 0 0"/>
      <geometry>
        <mesh filename="package://flexiv_description/meshes/Rizon4/collision/link4.stl"/>
      </geometry>
    </collision>
  </link>
  <link name="link5">
    <origin rpy="0.0 0.0 0.0" xyz="0.0 0.0 0.14"/>
    <mass value="2.3"/>
    <inertia ixx="0.01" ixy="0.0" ixz="0.0" iyy="0.01" iyz="0.001" izz="0.004"/>
    <visual name="shell">
      <origin rpy="0 0 0" xyz="0 0 0"/>
      <geometry>
        <mesh filename="package://flexiv_description/meshes/Rizon4/visual/link5.obj"/>
      </geometry>
    </visual>
    <visual name="ring">
      <origin rpy="0.0 0.0 0.0" xyz="0.0 0.0 -0.0025"/>
      <geometry>
        <mesh filename="package://flexiv_description/meshes/Rizon4/visual/ring.obj" scale="0.051 0.051 0.002"/>
      </geometry>
    </visual>
    <collision name="convex_mesh">
      <origin rpy="0 0 0" xyz="0 0 0"/>
      <geometry>
        <mesh filename="package://flexiv_description/meshes/Rizon4/collision/link5.stl"/>
      </geometry>
    </collision>
  </link>
  <link name="link6">
    <origin rpy="0.0 0.0 0.0" xyz="0.02 0.06 0.07"/>
    <mass value="2.2"/>
    <inertia ixx="0.01" ixy="0.0" ixz="-0.001" iyy="0.01" iyz="0.002" izz="0.004"/>
    <visual name="shell">
      <origin rpy="0 0 0" xyz="0 0 0"/>
      <geometry>
        <mesh filename="package://flexiv_description/meshes/Rizon4/visual/link6.obj"/>
      </geometry>
    </visual>
    <visual name="ring">
      <origin rpy="1.570796327 0.0 0.0" xyz="0.0 -0.0025 0.0"/>
      <geometry>
        <mesh filename="package://flexiv_description/meshes/Rizon4/visual/ring.obj" scale="0.051 0.051 0.002"/>
      </geometry>
    </visual>
    <collision name="convex_mesh">
      <origin rpy="0 0 0" xyz="0 0 0"/>
      <geometry>
        <mesh filename="package://flexiv_description/meshes/Rizon4/collision/link6.stl"/>
      </geometry>
    </collision>
  </link>
  <link name="link7">
    <origin rpy="0.0 0.0 0.0" xyz="0.0 0.0 0.03"/>
    <mass value="0.8"/>
    <inertia ixx="0.001" ixy="0.0" ixz="0.0" iyy="0.001" iyz="0.0" izz="0.001"/>
    <visual name="shell">
      <origin rpy="0 0 0" xyz="0 0 0"/>
      <geometry>
        <mesh filename="package://flexiv_description/meshes/Rizon4/visual/link7.obj"/>
      </geometry>
    </visual>
    <visual name="ring">
      <origin rpy="0.0 0.0 0.0" xyz="0.0 0.0 -0.0025"/>
      <geometry>
        <mesh filename="package://flexiv_description/meshes/Rizon4/visual/ring.obj" scale="0.051 0.051 0.002"/>
      </geometry>
    </visual>
    <collision name="convex_mesh">
      <origin rpy="0 0 0" xyz="0 0 0"/>
      <geometry>
        <mesh filename="package://flexiv_description/meshes/Rizon4/collision/link7.stl"/>
      </geometry>
    </collision>
  </link>
  <link name="flange">
    </link>
</robot>
